Workbook
Name page2: Memorial_Descritivo!$A$56
Name page3: Memorial_Descritivo!$A$108
Name Print_Area: Memorial_Descritivo!$A$1:$A$173

Sheet Dados
A1: PROJETO:
A2: {{finalidade_obra}}
A3: PROPRIETARIO:
A4: {{proprietario_1}}
A5: CPF:
A6: {{num_doc_1}}
A7: PROPRIETARIO:
A8: {{proprietario_2}}
A9: CPF:
A10: {{num_doc_2}}
A11: FINALIDADE DA OBRA:
A12: {{finalidade_obra}}
... A14: Alvenaria
A15: ÁREA DE CONSTRUÇÃO EXISTENTE: | B15: Nº ALVARÁ
A17: ÁREA DE CONSTRUÇÃO:
A18: {{area_construida_total}}
A19: ÁREA DE REFORMA:
A20: 0
A21: ÁREA TERRENO:
A22: {{area}}
A23: ENDEREÇO DA OBRA:
A24: LOGRADOURO e N°:
A25: {{confrontacao_frente}}
A26: LOTE:
A27: {{lote}}
A28: QUADRA:
A29: {{quadra}}
A30: LOTEAMENTO:
A31: {{loteamento}}
A32: ZONA:
A33: {{zona_zoneamento}}
A34: ="" & Dados!A25 & ", lote " & Dados!A27 & ", quadra " & Dados!A29 & ", LOTEAMENTO "& Dados!A31 &", SORRISO/MT." -> {{confrontacao_frente}}, lote {{lote}}, quadra {{quadra}}, LOTEAMENTO {{loteamento}}, SORRISO/MT.
A35: MATRICULA:
A36: {{matricula}}
A37: CEP: | B37: https://site.sorriso.mt.gov.br/consultacep
A38: {{cep}}
A39: Altura maxima:
A40: {{altura_maxima}}
A41: Numero de pavimentos:
A42: {{numero_pavimentos}}
...

Sheet Plan_Estatistica
A1: PLANILHA DE ESTATISTICA
A3: Proprietários: | C3: =Dados!A4 -> {{proprietario_1}} | G3: / | H3: =IF(AND(Dados!A8<>"", Dados!A10<>""), Dados!A8,"") -> {{proprietario_2}}
A4: CPF: | B4: =Dados!A6 -> {{num_doc_1}} | H4: =IF(Dados!A10<>"", "CPF: " & Dados!A10, "") -> CPF: {{num_doc_2}}
A6: 1 | B6: Zona | C6: Lote | D6: Quadra | G6: 2 | H6: Loteamento
B7: =Dados!A33 -> {{zona_zoneamento}} | C7: =Dados!A27 -> {{lote}} | D7: =Dados!A29 -> {{quadra}} | H7: =Dados!A31 -> {{loteamento}}
A9: 3 | B9: Área de construção (m²) | G9: 4 | H9: Área do Lote (m²)
E10: =Dados!A18 -> {{area_construida_total}} | H10: =Dados!A22 -> {{area}}
A12: 5 | B12: Área de existente (m²) | G12: 6 | H12: Área de Edificação Superior (m²)
B14: =IF(AND(Dados!A16<>"", Dados!B16<>""), Dados!B16,"") | E14: =IF(Dados!A16<>"",Dados!A16,"")
A16: 7 | B16: Piscina (m²) | G16: 8 | H16: Calçada (m²)
H17: 0
A19: 9 | B19: Área Const computável (m²) | D19: 10 | E19: Área Const não computável (m²) | I19: 11 | J19: Área Const Total (m²)
B20: =IF(E14<>"", E10+E14, E10) -> {{area_construida_total}} | E20: =B17+H17 -> 0 | J20: =B20 -> {{area_construida_total}}
A22: 12 | B22: Área de projeção da construção(m²) | G22: 13 | H22: Nº vagas estacionamento
B23: =B20 -> {{area_construida_total}} | H23: =Dados!A44 -> {{numero_vagas}}
A25: 14 | B25: Taxa de Permeabilidade | G25: 15 | H25: N. pavimentos | I25: 16 | J25: Altura máxima (m)
B26: =1-((B23)/H10) -> #VALUE! | H26: =Dados!A42 -> {{numero_pavimentos}} | J26: =Dados!A40 -> {{altura_maxima}}
A28: 17 | B28: Taxa de Ocupação (%) (Item 12x100/Item4) | G28: 18 | H28: Coeficiente de Aproveitamento (Item 9/Item4)
B29: =B23/H10 -> #VALUE! | H29: =B20/H10 -> #VALUE!
A31: 19 | B31: Finalidade | I31: =IF(Dados!A14=J31, "X", "") -> X | J31: Alvenaria
B32: =Dados!A12 -> {{finalidade_obra}} | I32: =IF(Dados!A14=J32, "X", "") | J32: Madeira
I33: =IF(Dados!A14=J33, "X", "") | J33: Pré-moldado
A35: Propietário: | H35: Resp. Técnico:
B39: =C3 -> {{proprietario_1}} | H39: =Dados!A54 -> LEANDRO DE SOUZA PEREIRA
B40: =B4 -> {{num_doc_1}} | H40: =Dados!A55 -> 1214579051
B43: =IF(AND(Dados!A8<>"", Dados!A10<>""), Dados!A8,"") -> {{proprietario_2}}
B44: =IF(Dados!A10<>"", "CPF: " & Dados!A10, "") -> CPF: {{num_doc_2}}
B46: =Dados!A59 -> Sorriso/MT, 28 de maio de 2026

Sheet Memorial_Descritivo
A2: MEMORIAL DESCRITIVO
A4: PROPRIETARIO:
A5: =Dados!A4 -> {{proprietario_1}}
A6: CPF:
A7: =Dados!A6 -> {{num_doc_1}}
A8: =IF(Dados!A8<>"", "PROPRIETARIO: "," ") -> PROPRIETARIO:
A9: =IF(AND(Dados!A8<>"", Dados!A10<>""), Dados!A8,"") -> {{proprietario_2}}
A10: =IF(Dados!A10<>"", "CPF: "," ") -> CPF:
A11: =IF(Dados!A10<>"", "CPF: " & Dados!A10, "") -> CPF: {{num_doc_2}}
A14: FINALIDADE DA OBRA:
A15: =Dados!A12 -> {{finalidade_obra}}
A17: ÁREA DE CONSTRUÇÃO:
A18: =Dados!A18 -> {{area_construida_total}}
A21: ÁREA TERRENO:
A22: =Dados!A22 -> {{area}}
A24: ENDEREÇO DA OBRA:
A25: =Dados!A34 -> {{confrontacao_frente}}, lote {{lote}}, quadra {{quadra}}, LOTEAMENTO {{loteamento}}, SORRISO/MT.
A27: Disposições Iniciais
A28: Este memorial tem como finalidade descrever as especificações de servições e materiais as serem aplicados na edificação visando auxiliar na interpretação do projeto.
A30: 1.Serviços Preliminares
A32: 1.1. Limpeza
A33: A área a ser construída deverá ser limpa e regularizada com maquinário adequado.
A35: 1.2. Locação da obra
A36: A obra deverá ser locada na forma convencional.
A38: 2.Infra estrutura
A40: 2.1. Sapatas
A41: As sapatas isoladas de concreto armado nas dimensões de 80x80x20cm, conforme projeto específico.
A42: 2.2. Vigas baldrames
A43: De concreto armado nas dimensões 15x30cm, conforme projeto específico.
... A67: 6.1. Cobertura
A68: ="Cobertura será do tipo " & Dados!A46 & ", com telhas de " & Dados!A48 & ", e inclinação de " & Dados!A50 & "%, sobre estrutura de madeira tipo cambará de boa qualidade." -> Cobertura será do tipo duas águas embutidas na platibanda, com telhas de {{tipo_telhado}}, e inclinação de {{inclinacao_telhado}}%, sobre estrutura de madeira tipo cambará de boa qualidade.
A69: ="Com forro "&Dados!A52&"." -> Com forro {{tipo_forro}}.
A71: 7.Instalações Elétricas
A73: 7.1. Rede Elétrica
A74: A serem executadas em conformidade com as normas específicas obedecendo às indicações no respectivo projeto. As luminárias serão do tipo lâmpadas fluorescentes e 15w e 20w.
A76: 8.Instalações Hidráulicas
A78: 8.1. Rede hidráulica
A79: A rede hidráulica será executada de acordo com o respectivo projeto.
A93: 9.Instalações Sanitárias
A95: 9.1. Rede Sanitária
...

Sheet Declaração
B2: À Secretaria Municipal da Cidade – SEMCID Departamento de Aprovação de Projetos
B3: AUTORIZAÇÃO PARA APROVAÇÃO DE PROJETO
B4: =IF(Dados!A8="", "Eu, ", "Nós, ") & Dados!A4 & ", portador(a) do CPF: " & Dados!A6 & IF(Dados!A8="", "", " e " & Dados!A8 & ", portador(a) do CPF: " & Dados!A10) & ", " & IF(Dados!A8="", "AUTORIZO ", "AUTORIZAMOS ") & "o profissional " & Dados!A54 & ", " & Dados!A56 & ", inscrito(a) no CREA RNP: " & Dados!A55 & ", a representar-" & IF(Dados!A8="", "me ", "nos ") & "junto à Prefeitura Municipal de Sorriso para protocolar, tramitar e aprovar o projeto arquitetônico referido no protocolo " & Dados!A62 & ", localizada na " & Dados!A34 & " registrado na matrícula " & Dados!A36 & ", bem como realizar todos os procedimentos necessários à obtenção do Alvará de Construção." -> Nós, {{proprietario_1}}, portador(a) do CPF: {{num_doc_1}} e {{proprietario_2}}, portador(a) do CPF: {{num_doc_2}}, AUTORIZAMOS o profissional LEANDRO DE SOUZA PEREIRA, ENG. CIVIL, inscrito(a) no CREA RNP: 1214579051, a representar-nos junto à Prefeitura Municipal de Sorriso para protocolar, tramitar e aprovar o projeto arquitetônico referido no protocolo AC0625-3XXXXX, localizada na {{confrontacao_frente}}, lote {{lote}}, quadra {{quadra}}, LOTEAMENTO {{loteamento}}, SORRISO/MT. registrado na matrícula {{matricula}}, bem como realizar todos os procedimentos necessários à obtenção do Alvará de Construção.
B6: Estou igualmente ciente de que todas as taxas decorrentes deste processo serão emitidas em nome(s) aqui representado(s), enquanto proprietário(s) do imóvel, e assumo total responsabilidade pelo seu pagamento.
B8: Por ser expressão da verdade e de minha livre vontade, firmo o presente.
B10: =Dados!A59 -> Sorriso/MT, 28 de maio de 2026
B15: =Dados!A4 -> {{proprietario_1}}
B16: =Dados!A6 -> {{num_doc_1}}
B19: =IF(AND(Dados!A8<>"", Dados!A10<>""), Dados!A8,"") -> {{proprietario_2}}
B20: =IF(Dados!A10<>"", "CPF: " & Dados!A10, "") -> CPF: {{num_doc_2}}
